import { render, screen, fireEvent } from '@testing-library/react';
import { describe, it, expect, vi, beforeEach } from 'vitest';
import ErrorBoundary from './ErrorBoundary';
import React from 'react';

// Component that throws an error for testing
const ThrowError = ({ shouldThrow }: { shouldThrow: boolean }) => {
  if (shouldThrow) {
    throw new Error('Test error');
  }
  return <div>No error</div>;
};

describe('ErrorBoundary', () => {
  // Suppress console.error for these tests
  const originalError = console.error;
  beforeEach(() => {
    console.error = vi.fn();
  });

  afterEach(() => {
    console.error = originalError;
  });

  it('renders children when there is no error', () => {
    render(
      <ErrorBoundary>
        <div>Test content</div>
      </ErrorBoundary>
    );
    
    expect(screen.getByText('Test content')).toBeInTheDocument();
  });

  it('renders error UI when child component throws', () => {
    render(
      <ErrorBoundary>
        <ThrowError shouldThrow={true} />
      </ErrorBoundary>
    );
    
    expect(screen.getByText('Something went wrong')).toBeInTheDocument();
    expect(screen.getByText(/We're sorry, but something unexpected happened/)).toBeInTheDocument();
  });

  it('shows error details in development mode', () => {
    const originalEnv = process.env.NODE_ENV;
    process.env.NODE_ENV = 'development';
    
    render(
      <ErrorBoundary>
        <ThrowError shouldThrow={true} />
      </ErrorBoundary>
    );
    
    expect(screen.getByText(/Error details/)).toBeInTheDocument();
    
    process.env.NODE_ENV = originalEnv;
  });

  it('renders custom fallback when provided', () => {
    const customFallback = <div>Custom error message</div>;
    
    render(
      <ErrorBoundary fallback={customFallback}>
        <ThrowError shouldThrow={true} />
      </ErrorBoundary>
    );
    
    expect(screen.getByText('Custom error message')).toBeInTheDocument();
  });

  it('resets error state when Try Again is clicked', () => {
    const { rerender } = render(
      <ErrorBoundary>
        <ThrowError shouldThrow={true} />
      </ErrorBoundary>
    );
    
    expect(screen.getByText('Something went wrong')).toBeInTheDocument();
    
    // Click Try Again
    fireEvent.click(screen.getByText('Try Again'));
    
    // Re-render with non-throwing component
    rerender(
      <ErrorBoundary>
        <ThrowError shouldThrow={false} />
      </ErrorBoundary>
    );
    
    expect(screen.getByText('No error')).toBeInTheDocument();
  });

  it('logs error to console', () => {
    render(
      <ErrorBoundary>
        <ThrowError shouldThrow={true} />
      </ErrorBoundary>
    );
    
    expect(console.error).toHaveBeenCalledWith(
      'Error caught by ErrorBoundary:',
      expect.any(Error),
      expect.any(Object)
    );
  });
});